#VRML_SIM R2023b utf8

EXTERNPROTO "https://raw.githubusercontent.com/cyberbotics/webots/R2023b/projects/objects/backgrounds/protos/TexturedBackground.proto"
EXTERNPROTO "https://raw.githubusercontent.com/cyberbotics/webots/R2023b/projects/objects/backgrounds/protos/TexturedBackgroundLight.proto"
EXTERNPROTO "https://raw.githubusercontent.com/cyberbotics/webots/R2023b/projects/objects/floors/protos/RectangleArena.proto"
EXTERNPROTO "https://raw.githubusercontent.com/cyberbotics/webots/R2023b/projects/objects/factory/containers/protos/WoodenBox.proto"

WorldInfo {
}
Viewpoint {
  orientation 0.48228701664363316 -0.3046872509428422 -0.8213190078708013 4.28763093080118
  position 0.2736217097328987 -1.0702440664052895 1.4236635868154073
}
TexturedBackground {
}
TexturedBackgroundLight {
}
RectangleArena {
}
WoodenBox {
  translation -0.27 0.01 0.046
  name "wooden box(2)"
  size 0.1 0.1 0.1
}
WoodenBox {
  translation 0.26 -0.24 0.046
  name "wooden box(1)"
  size 0.1 0.1 0.1
}
WoodenBox {
  translation -0.08 -0.24 0.046
  size 0.1 0.1 0.1
}
Robot {
  translation 0.11549875955622912 0.14403139339471363 0.03972007631782927
  rotation 0.18184882295323457 -0.6953216175689643 -0.6953120549305918 2.781854923171961
  children [
    DEF BODY Shape {
      appearance PBRAppearance {
        baseColor 0.917647 0.145098 0.145098
        roughness 1
        metalness 0
      }
      geometry Box {
        size 0.1 0.05 0.2
      }
    }
    DEF WHEEL1 HingeJoint {
      jointParameters HingeJointParameters {
        position 458.2643148927986
        anchor 0.06 0 0.05
      }
      device [
        RotationalMotor {
          name "wheel1"
        }
      ]
      endPoint Solid {
        translation 0.05999999999999997 3.6015722149074507e-06 0.04999844229220306
        rotation 0.1988044100858254 -0.9596960506972341 0.19864615980823516 4.672057587185882
        children [
          DEF WHEEL Shape {
            appearance PBRAppearance {
              baseColor 0.305882 0.898039 0.25098
              roughness 1
              metalness 0
            }
            geometry Cylinder {
              height 0.02
              radius 0.04
              subdivision 24
            }
          }
        ]
        boundingObject USE WHEEL
        physics Physics {
        }
      }
    }
    DEF WHEEL2 HingeJoint {
      jointParameters HingeJointParameters {
        position 99.89600007965427
        anchor -0.06 0 0.05
      }
      device [
        RotationalMotor {
          name "wheel2"
        }
      ]
      endPoint Solid {
        translation -0.06 0 0.05
        rotation -0.2979920341825419 0.9068631885622942 -0.29799312877041295 1.668408300098542
        children [
          USE WHEEL
        ]
        name "solid(1)"
        boundingObject USE WHEEL
        physics Physics {
        }
      }
    }
    DEF WHEEL3 HingeJoint {
      jointParameters HingeJointParameters {
        position 458.2643678071097
        anchor 0.06 0 -0.05
      }
      device [
        RotationalMotor {
          name "wheel3"
        }
      ]
      endPoint Solid {
        translation 0.06 0 -0.05
        rotation 0.1986273165247301 -0.9597364682155055 0.19862804612494278 4.671300329086552
        children [
          USE WHEEL
        ]
        name "solid(2)"
        boundingObject USE WHEEL
        physics Physics {
        }
      }
    }
    DEF WHEEL4 HingeJoint {
      jointParameters HingeJointParameters {
        position 99.8960594465928
        anchor -0.06 0 -0.05
      }
      device [
        RotationalMotor {
          name "wheel4"
        }
      ]
      endPoint Solid {
        translation -0.06 0 -0.05
        rotation -0.2979675053855886 0.9068793079665227 -0.29796859988336016 1.6683906099518058
        children [
          USE WHEEL
        ]
        name "solid(3)"
        boundingObject USE WHEEL
        physics Physics {
        }
      }
    }
    DEF DS_RIGHT DistanceSensor {
      translation -0.03 0 0.1
      rotation 0 1 0 -1.87079
      children [
        Shape {
          appearance PBRAppearance {
            baseColor 0.184314 0.596078 0.847059
            roughness 1
            metalness 0
          }
          geometry Box {
            size 0.01 0.01 0.01
          }
        }
      ]
      name "ds_right"
    }
    DEF DS_LEFT DistanceSensor {
      translation 0.03 0 0.1
      rotation 0 1 0 -1.27079
      children [
        Shape {
          appearance PBRAppearance {
            baseColor 0.184314 0.596078 0.847059
            roughness 1
            metalness 0
          }
          geometry Box {
            size 0.01 0.01 0.01
          }
        }
      ]
      name "ds_left"
    }
  ]
  name "robot(1)"
  boundingObject USE BODY
  physics Physics {
    density -1
    mass 1
  }
  controller "my_controller"
  controllerArgs [
    ""
  ]
  linearVelocity -0.019582304492916022 0.03487818016604365 -4.0276986931052096e-07
  angularVelocity -6.016388517188872e-06 -5.770853240577369e-06 9.169217888384867e-06
}
