#VRML_SIM R2023b utf8

EXTERNPROTO "https://raw.githubusercontent.com/cyberbotics/webots/R2023b/projects/objects/backgrounds/protos/TexturedBackground.proto"
EXTERNPROTO "https://raw.githubusercontent.com/cyberbotics/webots/R2023b/projects/objects/backgrounds/protos/TexturedBackgroundLight.proto"
EXTERNPROTO "https://raw.githubusercontent.com/cyberbotics/webots/R2023b/projects/objects/floors/protos/RectangleArena.proto"
EXTERNPROTO "https://raw.githubusercontent.com/cyberbotics/webots/R2023b/projects/objects/factory/containers/protos/WoodenBox.proto"

WorldInfo {
}
Viewpoint {
  orientation 0.42136859009643374 0.4564983126872801 -0.7836184031745362 1.9239124969830854
  position 0.36202651969172855 0.9390853539725713 1.9316675509722354
}
TexturedBackground {
}
TexturedBackgroundLight {
}
RectangleArena {
}
WoodenBox {
  translation 0.31 -0.09 0.046
  size 0.1 0.1 0.1
}
WoodenBox {
  translation -0.0351618 -0.349403 0.046
  name "wooden box(3)"
  size 0.1 0.1 0.1
}
WoodenBox {
  translation -0.32 -0.09 0.046
  name "wooden box(2)"
  size 0.1 0.1 0.1
}
WoodenBox {
  translation 0.31 0.27 0.046
  name "wooden box(1)"
  size 0.1 0.1 0.1
}
Robot {
  translation 0.2726319835694747 0.4650288024116737 0.02496311113894024
  rotation -0.89747745072263 0.4381966151857751 -0.0501791977231494 0.0005927550325193601
  children [
    DistanceSensor {
      translation 0.05 -0.015 0.02
      rotation 0 0 1 -0.2153003061004253
      children [
        DEF sensor Shape {
          appearance PBRAppearance {
          }
          geometry Box {
            size 0.005 0.005 0.005
          }
        }
      ]
      name "Rsensor"
      boundingObject USE sensor
      physics Physics {
      }
    }
    DistanceSensor {
      translation 0.05 0.015 0.02
      rotation 0 0 -1 -0.2149999938995747
      children [
        DEF sensor Shape {
          appearance PBRAppearance {
          }
          geometry Box {
            size 0.005 0.005 0.005
          }
        }
      ]
      name "Lsensor"
      boundingObject USE sensor
      physics Physics {
      }
    }
    HingeJoint {
      jointParameters HingeJointParameters {
        position 12129.213869190397
        axis 0 1 0
        anchor -0.05 0.03 -0.01
      }
      device [
        RotationalMotor {
          name "BLmotor"
        }
      ]
      endPoint Solid {
        translation -0.050047603168927875 0.03 -0.009993840591909506
        rotation -0.16878229619311036 -0.6972391533888813 0.6966850791235141 3.4762601956838743
        children [
          DEF wheel Shape {
            appearance PBRAppearance {
              baseColor 1 0 0
              roughness 1
              metalness 0
            }
            geometry Cylinder {
              height 0.005
              radius 0.015
            }
          }
        ]
        name "solid(3)"
        boundingObject USE wheel
        physics Physics {
        }
        linearVelocity -1.6475082038294656e-06 1.663699033687209e-05 5.441813359766828e-05
        angularVelocity -0.001073128133193006 3.999236807933553 -0.002059690494271868
      }
    }
    HingeJoint {
      jointParameters HingeJointParameters {
        position 4329.837898638091
        axis 0 1 0
        anchor -0.05 -0.03 -0.01
      }
      device [
        RotationalMotor {
          name "BRmotor"
        }
      ]
      endPoint Solid {
        translation -0.050031766570723175 -0.03 -0.010035984510341113
        rotation -0.8816943947546672 -0.33376059423210713 0.3334949174965516 4.58760066941698
        children [
          DEF wheel Shape {
            appearance PBRAppearance {
              baseColor 1 0 0
              roughness 1
              metalness 0
            }
            geometry Cylinder {
              height 0.005
              radius 0.015
            }
          }
        ]
        name "solid(2)"
        boundingObject USE wheel
        physics Physics {
        }
        linearVelocity -0.0001680153972830664 1.6599555737571743e-05 4.358960150973068e-05
        angularVelocity -0.0010731267884401716 3.999236784459225 -0.002059689928466306
      }
    }
    HingeJoint {
      jointParameters HingeJointParameters {
        position 12129.213855379305
        axis 0 1 0
        anchor 0.05 0.03 -0.01
      }
      device [
        RotationalMotor {
          name "FLmotor"
        }
      ]
      endPoint Solid {
        translation 0.049978031529828486 0.03 -0.009957322297176111
        rotation 0.16878555541549398 0.6972392260872814 -0.6966842167641608 2.806912008706637
        children [
          DEF wheel Shape {
            appearance PBRAppearance {
              baseColor 1 0 0
              roughness 1
              metalness 0
            }
            geometry Cylinder {
              height 0.005
              radius 0.015
            }
          }
        ]
        name "solid(1)"
        boundingObject USE wheel
        physics Physics {
        }
        linearVelocity 0.00015832982729116696 1.7503571441290478e-05 3.80105051082184e-05
        angularVelocity -0.0010731255850469892 3.9992368262468343 -0.002059700508958652
      }
    }
    HingeJoint {
      jointParameters HingeJointParameters {
        position 4329.837789067732
        axis 0 -5 0
        anchor 0.05 -0.03 -0.01
      }
      device [
        RotationalMotor {
          name "FRmotor"
        }
      ]
      endPoint Solid {
        translation 0.05 -0.030008 -0.01
        rotation -0.8817268898998482 0.3337176353311761 -0.3334519927913298 4.58763723757953
        children [
          DEF wheel Shape {
            appearance PBRAppearance {
              baseColor 1 0 0
              roughness 1
              metalness 0
            }
            geometry Cylinder {
              height 0.005
              radius 0.015
            }
          }
        ]
        boundingObject USE wheel
        physics Physics {
        }
        linearVelocity -9.57126059881652e-06 1.7363624369679798e-05 2.363140177232862e-06
        angularVelocity -0.001310694396004634 -4.00076201048894 0.002073916221996812
      }
    }
    DEF body Shape {
      appearance PBRAppearance {
        baseColor 0 1 0
      }
      geometry Box {
        size 0.1 0.05 0.05
      }
    }
  ]
  boundingObject USE body
  physics Physics {
  }
  controller "my_controller1"
  linearVelocity -1.7386373480454553e-05 2.829364464907972e-05 -6.964622281299043e-05
  angularVelocity -0.001131661757237805 -0.0007626092872071912 6.525215597225506e-06
}
