#VRML_SIM R2023b utf8

EXTERNPROTO "https://raw.githubusercontent.com/cyberbotics/webots/R2023b/projects/objects/backgrounds/protos/TexturedBackground.proto"
EXTERNPROTO "https://raw.githubusercontent.com/cyberbotics/webots/R2023b/projects/objects/backgrounds/protos/TexturedBackgroundLight.proto"
EXTERNPROTO "https://raw.githubusercontent.com/cyberbotics/webots/R2023b/projects/objects/floors/protos/RectangleArena.proto"
EXTERNPROTO "https://raw.githubusercontent.com/cyberbotics/webots/R2023b/projects/objects/factory/containers/protos/WoodenBox.proto"

WorldInfo {
}
Viewpoint {
  orientation 0.502225689882698 0.008578439797088307 -0.8646940307371712 3.28403849442367
  position 0.7800918636355585 -0.30286267052927174 1.3972483452202442
}
TexturedBackground {
}
TexturedBackgroundLight {
}
RectangleArena {
}
WoodenBox {
  translation 0.31 -0.09 0.046
  size 0.1 0.1 0.1
}
Robot {
  translation -0.06041903968988302 -0.12179232946115627 0.024961669145448742
  rotation 0.9465483687392856 0.3206006864829851 -0.03551598884496774 0.0001987680862878599
  children [
    DistanceSensor {
      translation 0.05 -0.015 0.02
      rotation 0 0 1 -0.2153003061004253
      children [
        DEF sensor Shape {
          appearance PBRAppearance {
          }
          geometry Box {
            size 0.005 0.005 0.005
          }
        }
      ]
      name "Rsensor"
      boundingObject USE sensor
      physics Physics {
      }
    }
    DistanceSensor {
      translation 0.05 0.015 0.02
      rotation 0 0 -1 -0.2149999938995747
      children [
        DEF sensor Shape {
          appearance PBRAppearance {
          }
          geometry Box {
            size 0.005 0.005 0.005
          }
        }
      ]
      name "Lsensor"
      boundingObject USE sensor
      physics Physics {
      }
    }
    HingeJoint {
      jointParameters HingeJointParameters {
        position 89.95444570541062
        axis 0 1 0
        anchor -0.05 0.03 -0.01
      }
      device [
        RotationalMotor {
          name "BLmotor"
        }
      ]
      endPoint Solid {
        translation -0.05004097879518432 0.03 -0.010024994766357032
        rotation -0.4171037759664838 -0.6429162453223611 0.6424041886344601 3.932479155469448
        children [
          DEF wheel Shape {
            appearance PBRAppearance {
              baseColor 1 0 0
              roughness 1
              metalness 0
            }
            geometry Cylinder {
              height 0.005
              radius 0.015
            }
          }
        ]
        name "solid(3)"
        boundingObject USE wheel
        physics Physics {
        }
        linearVelocity -4.044948922107646e-12 -1.866659253863947e-13 -4.2218918635286665e-14
        angularVelocity -1.0588498994688192e-13 -3.362824391105269e-10 1.2493926337969282e-11
      }
    }
    HingeJoint {
      jointParameters HingeJointParameters {
        position 96.379763293515
        axis 0 1 0
        anchor -0.05 -0.03 -0.01
      }
      device [
        RotationalMotor {
          name "BRmotor"
        }
      ]
      endPoint Solid {
        translation -0.050040637942649395 -0.03 -0.009974454792676031
        rotation -0.36379914988704015 -0.6589161978408995 0.6583916940274683 3.8399340359807663
        children [
          DEF wheel Shape {
            appearance PBRAppearance {
              baseColor 1 0 0
              roughness 1
              metalness 0
            }
            geometry Cylinder {
              height 0.005
              radius 0.015
            }
          }
        ]
        name "solid(2)"
        boundingObject USE wheel
        physics Physics {
        }
        linearVelocity -7.679117698374084e-12 -1.876435562737063e-13 -6.219751409424865e-14
        angularVelocity 1.5965583912790954e-14 -7.077349578410362e-10 1.2424590376035167e-11
      }
    }
    HingeJoint {
      jointParameters HingeJointParameters {
        position 89.95444589058636
        axis 0 1 0
        anchor 0.05 0.03 -0.01
      }
      device [
        RotationalMotor {
          name "FLmotor"
        }
      ]
      endPoint Solid {
        translation 0.049956153259562326 0.03 -0.009980468913164085
        rotation 0.417102121514335 0.6429166379293069 -0.6424048699238802 2.3507024384184234
        children [
          DEF wheel Shape {
            appearance PBRAppearance {
              baseColor 1 0 0
              roughness 1
              metalness 0
            }
            geometry Cylinder {
              height 0.005
              radius 0.015
            }
          }
        ]
        name "solid(1)"
        boundingObject USE wheel
        physics Physics {
        }
        linearVelocity -6.559308674932202e-12 1.8852598482542086e-13 3.003071867682166e-14
        angularVelocity -1.0778747744815825e-13 -5.762717631854658e-10 1.2449079356894912e-11
      }
    }
    HingeJoint {
      jointParameters HingeJointParameters {
        position 96.37976449125996
        axis 0 -5 0
        anchor 0.05 -0.03 -0.01
      }
      device [
        RotationalMotor {
          name "FRmotor"
        }
      ]
      endPoint Solid {
        translation 0.05 -0.030008 -0.01
        rotation -0.36379870360352007 0.6589163211393867 -0.6583918172278074 3.8399332472564485
        children [
          DEF wheel Shape {
            appearance PBRAppearance {
              baseColor 1 0 0
              roughness 1
              metalness 0
            }
            geometry Cylinder {
              height 0.005
              radius 0.015
            }
          }
        ]
        boundingObject USE wheel
        physics Physics {
        }
        linearVelocity 7.64526527104828e-12 1.8798380773883458e-13 5.93075276309326e-14
        angularVelocity -4.2156527554659406e-14 7.582590734744015e-10 1.2701136068615057e-11
      }
    }
    DEF body Shape {
      appearance PBRAppearance {
        baseColor 0 1 0
      }
      geometry Box {
        size 0.1 0.05 0.05
      }
    }
  ]
  boundingObject USE body
  physics Physics {
  }
  controller "my_controller1"
  linearVelocity -1.168872448326578e-12 9.601650056571267e-16 1.1414113078000828e-14
  angularVelocity 1.196988408114922e-14 -9.21526672439281e-13 1.2557762440288023e-11
}
